#VRML_SIM R2020a utf8
WorldInfo {
  basicTimeStep 16
  physicsDisableTime 0
  defaultDamping Damping {
    linear 1
    angular 0
  }
}
Viewpoint {
  fieldOfView 1
  orientation -0.2739981313221389 -0.9574425868863756 0.09071227506958869 5.5556801221586305
  position 1.2549319331255906 0.4157967574807294 1.8292777926536161
}
TexturedBackground {
}
TexturedBackgroundLight {
}
Floor {
  size 3 3
}
DEF WALL1 Solid {
  translation 0 0.1 -1.5
  children [
    DEF WALL_SHAPE Shape {
      appearance PBRAppearance {
        baseColor 0 0 1
        roughness 0.5
        metalness 0
      }
      geometry Box {
        size 3 0.2 0.02
      }
    }
  ]
  name "solid(1)"
  boundingObject USE WALL_SHAPE
}
DEF WALL2 Solid {
  translation 0 0.1 1.5
  children [
    USE WALL_SHAPE
  ]
  name "solid(2)"
  boundingObject USE WALL_SHAPE
}
DEF WALL3 Solid {
  translation 1.5 0.1 0
  rotation 0 1 0 1.5708
  children [
    USE WALL_SHAPE
  ]
  name "solid(3)"
  boundingObject USE WALL_SHAPE
}
DEF WALL4 Solid {
  translation -1.5 0.1 0
  rotation 0 1 0 1.5708
  children [
    USE WALL_SHAPE
  ]
  name "solid(4)"
  boundingObject USE WALL_SHAPE
}
Robot {
  translation 0 0.12 0
  rotation 0 1 0 3.14159
  children [
    DEF BODY Shape {
      appearance PBRAppearance {
        roughness 1
        metalness 0
      }
      geometry Box {
        size 0.15 0.12 0.44
      }
    }
    DEF WHEEL1 HingeJoint {
      jointParameters HingeJointParameters {
        anchor 0.075 0 0.11
      }
      device [
        RotationalMotor {
          name "wheel1"
        }
      ]
      endPoint Solid {
        translation 0.095 0 0.11
        rotation 0 0 1 1.57
        children [
          DEF WHEEL Shape {
            appearance PBRAppearance {
            }
            geometry Cylinder {
              height 0.04
              radius 0.08
            }
          }
        ]
        boundingObject USE WHEEL
        physics DEF WHEEL_PH Physics {
        }
      }
    }
    DEF WHEEL2 HingeJoint {
      jointParameters HingeJointParameters {
        anchor -0.075 0 0.11
      }
      device [
        RotationalMotor {
          name "wheel2"
        }
      ]
      endPoint Solid {
        translation -0.095 0 0.11
        rotation 0 0 1 1.57
        children [
          USE WHEEL
        ]
        name "solid(1)"
        boundingObject USE WHEEL
        physics USE WHEEL_PH
      }
    }
    DEF WHEEL3 HingeJoint {
      jointParameters HingeJointParameters {
        anchor 0.075 0 -0.11
      }
      device [
        RotationalMotor {
          name "wheel3"
        }
      ]
      endPoint Solid {
        translation 0.095 0 -0.11
        rotation 0 0 1 1.57
        children [
          USE WHEEL
        ]
        name "solid(2)"
        boundingObject USE WHEEL
        physics USE WHEEL_PH
      }
    }
    DEF WHEEL4 HingeJoint {
      jointParameters HingeJointParameters {
        anchor -0.075 0 -0.11
      }
      device [
        RotationalMotor {
          name "wheel4"
        }
      ]
      endPoint Solid {
        translation -0.095 0 -0.11
        rotation 0 0 1 1.57
        children [
          USE WHEEL
        ]
        name "solid(3)"
        boundingObject USE WHEEL
        physics USE WHEEL_PH
      }
    }
    DEF ACCELEROMETER Accelerometer {
    }
    DistanceSensor {
      translation -0.03 0.02 0.23
      rotation 0 -1 0 1.7607
      children [
        DEF sensorshape Shape {
          appearance PBRAppearance {
            baseColor 0.9 0.9 0.9
          }
          geometry Capsule {
            height 0.01
            radius 0.01
          }
        }
      ]
      name "distance sensor front right"
      lookupTable [
        0 0 0
        5 5000 0
      ]
    }
    DistanceSensor {
      translation 0.03 0.02 0.23
      rotation 0 -1 0 1.3807
      children [
        USE sensorshape
      ]
      name "distance sensor front left"
      lookupTable [
        0 0 0
        5 5000 0
      ]
      type "sonar"
    }
    Compass {
    }
  ]
  name "6_joint_arm"
  boundingObject USE BODY
  physics Physics {
  }
  controller "six_joint_robot_arm"
}
